Workbook

Sheet README
A1: European FBO & Ground Handling — Market Research
A3: Purpose | B3: Identify regional and independent FBOs and ground handlers across European secondary hubs as potential customers for a flight operations dashboard platform.
A4: Scope | B4: Excludes the global mega-handlers (Menzies, Swissport, dnata, WFS-cargo) from the prospecting focus, but they are noted where they are the only operator at an airport, so you know the competitive landscape.
A5: Source date | B5: Research compiled April 2026 from public sources: AENA, airport B2B portals, company websites, trade press (Regional Gateway, AIN, Business Air News), CAPA, LinkedIn.
A7: Column guide
A8: Type | B8: FBO = business/private aviation terminal operator. Handler = commercial airline ground handler. Both = operates in both segments.
A9: Segment | B9: Biz Av = business aviation focus. Commercial = scheduled airline handling. Cargo = freight handling. Mixed = more than one.
A10: Employees | B10: Approximate, from public sources. Blank where no reliable public figure exists.
A11: Modernization signal | B11: INFERRED from public signals only — tech press releases, ISO certifications, visible digital tooling, recent equipment investment, IS-BAH accreditation. NOT a verified audit. Use as a starting hypothesis for qualification calls, not as ground truth.
A12: Modern | B12: Clear digital / recent tech investment signals (e.g., IS-BAH Stage 2, published ISO 27001, own ops apps, recent GSE electrification).
A13: Mixed | B13: Established operator with some modernization signals but likely still mixed workflows.
A14: Traditional | B14: Few public modernization signals. Likely candidate for digital transformation — often the most interesting prospect.
A15: Unknown | B15: Not enough public info to assess.
A17: Prospecting tip | B17: The 'Traditional' and 'Mixed' rows are usually the highest-value prospects for a dashboard product. 'Modern' operators may already have an internal solution or a competitor product. Regional independents (G.A.S. Spain, GH Italia, Goldair, Portway, Sky Valet Connect affiliates) are the sweet spot — large enough to have budget, small enough to buy without a 12-month procurement cycle.
A19: Important caveat | B19: Aena's 2023 handling tender reshuffled Spanish licenses effective April 2024. Aviapartner gained Madrid, Barcelona, Valencia, Alicante, Ibiza, Bilbao. IAG formed 'South Europe Ground Services' (South) covering 38 airports. Data reflects the post-2024 landscape where verifiable; some sources predate it and are noted.

Sheet FBO & Handler Directory
A1: Country | B1: City | C1: Airport | D1: ICAO | E1: IATA | F1: Company | G1: Type | H1: Segment focus | I1: Parent / Network | J1: Approx. employees | K1: Modernization signal | L1: Notes | M1: Priority (you fill)
A2: Spain | B2: Madrid | C2: Adolfo Suárez Madrid-Barajas | D2: LEMD | E2: MAD | F2: General Aviation Service (G.A.S.) | G2: FBO | H2: Biz Av | I2: Independent (family-owned, since 1979) | J2: ~100 (group-wide) | K2: Modern | L2: Nine-base Spanish FBO network. Invested €200k in new handling equipment in early 2025; first GA handler in Spain authorised to operate TowFLEXX TF5 electric tugs. Flagship independent.
A3: Spain | B3: Madrid | C3: Adolfo Suárez Madrid-Barajas | D3: LEMD | E3: MAD | F3: South Europe Ground Services (South) | G3: Handler | H3: Commercial | I3: IAG Group (Iberia spin-off) | J3: ~8,700 | K3: Mixed | L3: Formed 2024 from Iberia Airport Services. Present at 38 Spanish airports. New entity — internal systems likely inherited from Iberia, being restructured; possible greenfield for new tooling.
A4: Spain | B4: Madrid | C4: Adolfo Suárez Madrid-Barajas | D4: LEMD | E4: MAD | F4: WFS (Worldwide Flight Services) | G4: Handler | H4: Cargo + Commercial | I4: Platinum Equity / SATS | J4: Not disclosed (Spain) | K4: Mixed | L4: Cargo leader in MAD, BCN, VLC, BIO. Added full passenger/ramp in Madrid + Seville 2023. Global group, but Spain is a discrete P&L — worth approaching at country-manager level.
A5: Spain | B5: Madrid | C5: Adolfo Suárez Madrid-Barajas | D5: LEMD | E5: MAD | F5: Sky Valet Spain | G5: FBO | H5: Biz Av | I5: Aéroports de la Côte d'Azur (ACA) | J5: Not disclosed | K5: Modern | L5: Part of 45-FBO pan-European network. Centralised OCC in Spain at +34 916 782 648. Likely has internal tools but satellite bases may operate semi-independently.
A6: Spain | B6: Barcelona | C6: Barcelona–El Prat | D6: LEBL | E6: BCN | F6: General Aviation Service (G.A.S.) | G6: FBO | H6: Biz Av | I6: Independent | J6: Part of ~100 group | K6: Modern | L6: TowFLEXX electric tug already deployed here. Strong biz av hub — F1, Mobile World Congress peaks.
A7: Spain | B7: Barcelona | C7: Barcelona–El Prat | D7: LEBL | E7: BCN | F7: ExecuJet Barcelona | G7: FBO | H7: Biz Av | I7: Luxaviation Group | J7: Not disclosed | K7: Modern | L7: One of four ExecuJet Spanish FBOs (BCN, GRO, IBZ, VLC). Spanish HQ in Palma. Global group tools.
A8: Spain | B8: Barcelona | C8: Barcelona–El Prat | D8: LEBL | E8: BCN | F8: Sky Valet Barcelona | G8: FBO | H8: Biz Av | I8: Aéroports de la Côte d'Azur | J8: Not disclosed | K8: Modern | L8: ACA network base.
A9: Spain | B9: Valencia | C9: Valencia Airport (Manises) | D9: LEVC | E9: VLC | F9: General Aviation Service (G.A.S.) | G9: FBO | H9: Biz Av | I9: Independent | J9: Part of ~100 group | K9: Modern | L9: Valencia Airport, Edificio Bloque Técnico. Terminal Aviación General.
A10: Spain | B10: Valencia | C10: Valencia Airport (Manises) | D10: LEVC | E10: VLC | F10: ExecuJet Valencia | G10: FBO | H10: Biz Av | I10: Luxaviation | J10: Not disclosed | K10: Modern
A11: Spain | B11: Valencia | C11: Valencia Airport (Manises) | D11: LEVC | E11: VLC | F11: Sky Valet Valencia | G11: FBO | H11: Biz Av | I11: ACA | J11: Not disclosed | K11: Modern
A12: Spain | B12: Valencia | C12: Valencia Airport (Manises) | D12: LEVC | E12: VLC | F12: Aviapartner Valencia | G12: Handler | H12: Commercial | I12: Aviapartner (Belgian independent) | J12: Part of ~12,000 group | K12: Mixed | L12: Won license in 2023 Aena tender, effective April 2024. Committed to full GSE electrification — modernisation in progress, good timing for dashboard pitch.
A13: Spain | B13: Bilbao | C13: Bilbao Airport | D13: LEBB | E13: BIO | F13: Aviapartner Bilbao | G13: Handler | H13: Commercial | I13: Aviapartner | J13: Part of ~12,000 group | K13: Mixed | L13: New 2024 license. Aviapartner is actively modernising fleet; central ops may still be handler-oriented rather than biz-av.
A14: Spain | B14: Bilbao | C14: Bilbao Airport | D14: LEBB | E14: BIO | F14: Groundforce Bilbao | G14: Handler | H14: Commercial | I14: Globalia (Spanish group) | J14: Part of Groundforce group (~5,000+) | K14: Traditional | L14: Groundforce is the legacy #2 handler in Spain. Labour-intensive, pre-digital culture at many stations — strong prospect for operational dashboard tooling.
A15: Spain | B15: Bilbao | C15: Bilbao Airport | D15: LEBB | E15: BIO | F15: WFS Bilbao | G15: Handler | H15: Cargo | I15: WFS/Platinum Equity | J15: Not disclosed | K15: Mixed | L15: WFS is the largest cargo handler in Bilbao per company statement.
A16: Spain | B16: Palma de Mallorca | C16: Palma de Mallorca Airport | D16: LEPA | E16: PMI | F16: Mallorcair | G16: FBO | H16: Biz Av | I16: Independent | J16: Not disclosed | K16: Modern | L16: Awarded FBO1 Executive Terminal contract. EMEA Top 10 FBO (Business Air News). Strong local brand — hottest island for biz av in Europe.
A17: Spain | B17: Palma de Mallorca | C17: Palma de Mallorca Airport | D17: LEPA | E17: PMI | F17: General Aviation Service (G.A.S.) | G17: FBO | H17: Biz Av | I17: Independent | J17: Part of ~100 group | K17: Modern | L17: Terminal Ejecutiva. Station Mgr: Sebastia Godia Ozonas.
A18: Spain | B18: Palma de Mallorca | C18: Palma de Mallorca Airport | D18: LEPA | E18: PMI | F18: ExecuJet Palma (Spanish HQ) | G18: FBO | H18: Biz Av | I18: Luxaviation | J18: Not disclosed | K18: Modern | L18: Headquarters for ExecuJet's four Spanish FBOs.
A19: Spain | B19: Palma de Mallorca | C19: Palma de Mallorca Airport | D19: LEPA | E19: PMI | F19: Sky Valet Palma | G19: FBO | H19: Biz Av | I19: ACA | J19: Not disclosed | K19: Modern
A20: Spain | B20: Palma de Mallorca | C20: Palma de Mallorca Airport | D20: LEPA | E20: PMI | F20: AviaVIP Palma | G20: FBO | H20: Biz Av | I20: AviaVIP (regional group) | J20: Not disclosed | K20: Mixed | L20: Also present in Málaga. Smaller player — good early-adopter profile.
A21: Spain | B21: Palma de Mallorca | C21: Palma de Mallorca Airport | D21: LEPA | E21: PMI | F21: South Europe Ground Services (South) | G21: Handler | H21: Commercial | I21: IAG | J21: Part of ~8,700 | K21: Mixed | L21: PMI is a South network node.
A22: Spain | B22: Ibiza | C22: Ibiza Airport | D22: LEIB | E22: IBZ | F22: General Aviation Service (G.A.S.) | G22: FBO | H22: Biz Av | I22: Independent | J22: Part of ~100 group | K22: Modern
A23: Spain | B23: Ibiza | C23: Ibiza Airport | D23: LEIB | E23: IBZ | F23: ExecuJet Ibiza | G23: FBO | H23: Biz Av | I23: Luxaviation | J23: ~4+ local | K23: Modern | L23: IS-BAH Stage 2 accredited, opened 2011 (took over from Assistair). 24h operations. Summer-peaked — ops intensity spikes hugely Jun-Sep.
A24: Spain | B24: Ibiza | C24: Ibiza Airport | D24: LEIB | E24: IBZ | F24: Sky Valet Ibiza | G24: FBO | H24: Biz Av | I24: ACA | J24: Not disclosed | K24: Modern
A25: Spain | B25: Ibiza | C25: Ibiza Airport | D25: LEIB | E25: IBZ | F25: Aviapartner Ibiza | G25: Handler | H25: Commercial | I25: Aviapartner | J25: Part of ~12,000 | K25: Mixed | L25: New 2024 license.
A26: Spain | B26: Málaga | C26: Málaga–Costa del Sol Airport | D26: LEMG | E26: AGP | F26: General Aviation Service (G.A.S.) | G26: FBO | H26: Biz Av | I26: Independent | J26: Part of ~100 group | K26: Modern
A27: Spain | B27: Málaga | C27: Málaga–Costa del Sol Airport | D27: LEMG | E27: AGP | F27: Aviapartner Málaga FBO | G27: FBO + Handler | H27: Biz Av + Commercial | I27: Aviapartner | J27: Part of ~12,000 | K27: Mixed | L27: Separate Málaga FBO S.A. entity. Handler since 2015. GSE electrification commitment under new license.
A28: Spain | B28: Málaga | C28: Málaga–Costa del Sol Airport | D28: LEMG | E28: AGP | F28: AviaVIP Málaga | G28: FBO | H28: Biz Av | I28: AviaVIP | J28: Not disclosed | K28: Mixed | L28: +34 661 829 722. Good smaller-operator prospect.
A29: Spain | B29: Málaga | C29: Málaga–Costa del Sol Airport | D29: LEMG | E29: AGP | F29: Sky Valet Málaga | G29: FBO | H29: Biz Av | I29: ACA | J29: Not disclosed | K29: Modern
A30: Spain | B30: Málaga | C30: Málaga–Costa del Sol Airport | D30: LEMG | E30: AGP | F30: Jetex Málaga | G30: FBO | H30: Biz Av | I30: Jetex (UAE-based) | J30: Not disclosed | K30: Modern | L30: Global group with own proprietary ops platform.
A31: Spain | B31: Alicante | C31: Alicante-Elche | D31: LEAL | E31: ALC | F31: General Aviation Service (G.A.S.) | G31: FBO | H31: Biz Av | I31: Independent | J31: Part of ~100 group | K31: Modern | L31: Station Mgr: Víctor San Román Zabala. First Spanish GA handler authorised for TowFLEXX TF5.
A32: Spain | B32: Alicante | C32: Alicante-Elche | D32: LEAL | E32: ALC | F32: Aviapartner Alicante | G32: Handler | H32: Commercial | I32: Aviapartner | J32: Part of ~12,000 | K32: Mixed
A33: Spain | B33: Girona | C33: Girona-Costa Brava | D33: LEGE | E33: GRO | F33: General Aviation Service (G.A.S.) | G33: FBO | H33: Biz Av | I33: Independent | J33: Part of ~100 group | K33: Modern
A34: Spain | B34: Girona | C34: Girona-Costa Brava | D34: LEGE | E34: GRO | F34: ExecuJet Girona | G34: FBO | H34: Biz Av | I34: Luxaviation | J34: Not disclosed | K34: Modern
A35: Spain | B35: Girona | C35: Girona-Costa Brava | D35: LEGE | E35: GRO | F35: Sky Valet Girona | G35: FBO | H35: Biz Av | I35: ACA | J35: Not disclosed | K35: Modern
A36: Spain | B36: Granada | C36: FGL Granada Jaén | D36: LEGR | E36: GRX | F36: General Aviation Service (G.A.S.) | G36: FBO | H36: Biz Av | I36: Independent | J36: Part of ~100 group | K36: Modern
A37: Spain | B37: Santiago de Compostela | C37: Santiago-Rosalía de Castro | D37: LEST | E37: SCQ | F37: Sky Valet Santiago | G37: FBO | H37: Biz Av | I37: ACA | J37: Not disclosed | K37: Modern
A38: Spain | B38: Santiago de Compostela | C38: Santiago-Rosalía de Castro | D38: LEST | E38: SCQ | F38: WFS Santiago | G38: Handler | H38: Commercial + Cargo | I38: WFS | J38: Not disclosed | K38: Mixed | L38: New from 2023 license round.
A39: Spain | B39: A Coruña | C39: A Coruña Airport | D39: LECO | E39: LCG | F39: Sky Valet A Coruña | G39: FBO | H39: Biz Av | I39: ACA | J39: Not disclosed | K39: Modern
A40: Spain | B40: Seville | C40: Seville Airport | D40: LEZL | E40: SVQ | F40: WFS Seville | G40: Handler | H40: Commercial + Cargo | I40: WFS | J40: Not disclosed | K40: Mixed | L40: Won 2023 tender for full passenger + ramp.
...

Sheet Summary by Country
A1: Country rollup
A2: Country | B2: Total operators listed | C2: Modern | D2: Mixed | E2: Traditional
A3: Spain | B3: =COUNTIF('FBO & Handler Directory'!A:A,A3) -> 42 | C3: =COUNTIFS('FBO & Handler Directory'!A:A,A3,'FBO & Handler Directory'!K:K,"Modern") -> 25 | D3: =COUNTIFS('FBO & Handler Directory'!A:A,A3,'FBO & Handler Directory'!K:K,"Mixed") -> 15 | E3: =COUNTIFS('FBO & Handler Directory'!A:A,A3,'FBO & Handler Directory'!K:K,"Traditional") -> 2
A4: Italy | B4: =COUNTIF('FBO & Handler Directory'!A:A,A4) -> 18 | C4: =COUNTIFS('FBO & Handler Directory'!A:A,A4,'FBO & Handler Directory'!K:K,"Modern") -> 4 | D4: =COUNTIFS('FBO & Handler Directory'!A:A,A4,'FBO & Handler Directory'!K:K,"Mixed") -> 1 | E4: =COUNTIFS('FBO & Handler Directory'!A:A,A4,'FBO & Handler Directory'!K:K,"Traditional") -> 13
A5: France | B5: =COUNTIF('FBO & Handler Directory'!A:A,A5) -> 22 | C5: =COUNTIFS('FBO & Handler Directory'!A:A,A5,'FBO & Handler Directory'!K:K,"Modern") -> 14 | D5: =COUNTIFS('FBO & Handler Directory'!A:A,A5,'FBO & Handler Directory'!K:K,"Mixed") -> 6 | E5: =COUNTIFS('FBO & Handler Directory'!A:A,A5,'FBO & Handler Directory'!K:K,"Traditional") -> 2
A6: Germany | B6: =COUNTIF('FBO & Handler Directory'!A:A,A6) -> 11 | C6: =COUNTIFS('FBO & Handler Directory'!A:A,A6,'FBO & Handler Directory'!K:K,"Modern") -> 3 | D6: =COUNTIFS('FBO & Handler Directory'!A:A,A6,'FBO & Handler Directory'!K:K,"Mixed") -> 0 | E6: =COUNTIFS('FBO & Handler Directory'!A:A,A6,'FBO & Handler Directory'!K:K,"Traditional") -> 8
A7: Portugal | B7: =COUNTIF('FBO & Handler Directory'!A:A,A7) -> 12 | C7: =COUNTIFS('FBO & Handler Directory'!A:A,A7,'FBO & Handler Directory'!K:K,"Modern") -> 7 | D7: =COUNTIFS('FBO & Handler Directory'!A:A,A7,'FBO & Handler Directory'!K:K,"Mixed") -> 5 | E7: =COUNTIFS('FBO & Handler Directory'!A:A,A7,'FBO & Handler Directory'!K:K,"Traditional") -> 0
A8: Greece | B8: =COUNTIF('FBO & Handler Directory'!A:A,A8) -> 13 | C8: =COUNTIFS('FBO & Handler Directory'!A:A,A8,'FBO & Handler Directory'!K:K,"Modern") -> 3 | D8: =COUNTIFS('FBO & Handler Directory'!A:A,A8,'FBO & Handler Directory'!K:K,"Mixed") -> 10 | E8: =COUNTIFS('FBO & Handler Directory'!A:A,A8,'FBO & Handler Directory'!K:K,"Traditional") -> 0
A9: UK | B9: =COUNTIF('FBO & Handler Directory'!A:A,A9) -> 6 | C9: =COUNTIFS('FBO & Handler Directory'!A:A,A9,'FBO & Handler Directory'!K:K,"Modern") -> 1 | D9: =COUNTIFS('FBO & Handler Directory'!A:A,A9,'FBO & Handler Directory'!K:K,"Mixed") -> 5 | E9: =COUNTIFS('FBO & Handler Directory'!A:A,A9,'FBO & Handler Directory'!K:K,"Traditional") -> 0
A10: Denmark | B10: =COUNTIF('FBO & Handler Directory'!A:A,A10) -> 2 | C10: =COUNTIFS('FBO & Handler Directory'!A:A,A10,'FBO & Handler Directory'!K:K,"Modern") -> 1 | D10: =COUNTIFS('FBO & Handler Directory'!A:A,A10,'FBO & Handler Directory'!K:K,"Mixed") -> 1 | E10: =COUNTIFS('FBO & Handler Directory'!A:A,A10,'FBO & Handler Directory'!K:K,"Traditional") -> 0
A11: Sweden | B11: =COUNTIF('FBO & Handler Directory'!A:A,A11) -> 4 | C11: =COUNTIFS('FBO & Handler Directory'!A:A,A11,'FBO & Handler Directory'!K:K,"Modern") -> 3 | D11: =COUNTIFS('FBO & Handler Directory'!A:A,A11,'FBO & Handler Directory'!K:K,"Mixed") -> 1 | E11: =COUNTIFS('FBO & Handler Directory'!A:A,A11,'FBO & Handler Directory'!K:K,"Traditional") -> 0
A12: Norway | B12: =COUNTIF('FBO & Handler Directory'!A:A,A12) -> 5 | C12: =COUNTIFS('FBO & Handler Directory'!A:A,A12,'FBO & Handler Directory'!K:K,"Modern") -> 4 | D12: =COUNTIFS('FBO & Handler Directory'!A:A,A12,'FBO & Handler Directory'!K:K,"Mixed") -> 1 | E12: =COUNTIFS('FBO & Handler Directory'!A:A,A12,'FBO & Handler Directory'!K:K,"Traditional") -> 0
A13: Finland | B13: =COUNTIF('FBO & Handler Directory'!A:A,A13) -> 1 | C13: =COUNTIFS('FBO & Handler Directory'!A:A,A13,'FBO & Handler Directory'!K:K,"Modern") -> 1 | D13: =COUNTIFS('FBO & Handler Directory'!A:A,A13,'FBO & Handler Directory'!K:K,"Mixed") -> 0 | E13: =COUNTIFS('FBO & Handler Directory'!A:A,A13,'FBO & Handler Directory'!K:K,"Traditional") -> 0
A14: Belgium | B14: =COUNTIF('FBO & Handler Directory'!A:A,A14) -> 4 | C14: =COUNTIFS('FBO & Handler Directory'!A:A,A14,'FBO & Handler Directory'!K:K,"Modern") -> 0 | D14: =COUNTIFS('FBO & Handler Directory'!A:A,A14,'FBO & Handler Directory'!K:K,"Mixed") -> 4 | E14: =COUNTIFS('FBO & Handler Directory'!A:A,A14,'FBO & Handler Directory'!K:K,"Traditional") -> 0
... A23: Malta | B23: =COUNTIF('FBO & Handler Directory'!A:A,A23) -> 1 | C23: =COUNTIFS('FBO & Handler Directory'!A:A,A23,'FBO & Handler Directory'!K:K,"Modern") -> 0 | D23: =COUNTIFS('FBO & Handler Directory'!A:A,A23,'FBO & Handler Directory'!K:K,"Mixed") -> 1 | E23: =COUNTIFS('FBO & Handler Directory'!A:A,A23,'FBO & Handler Directory'!K:K,"Traditional") -> 0
A24: TOTAL | B24: =SUM(B3:B23) -> 164 | C24: =SUM(C3:C23) -> 76 | D24: =SUM(D3:D23) -> 57 | E24: =SUM(E3:E23) -> 31

Sheet Top prospects shortlist
A1: High-signal prospects for a flight-ops dashboard
A2: Criteria: (1) independent or loose network, (2) multi-station ops (pain of coordination), (3) not already using a global parent's internal system, (4) recent investment or growth signal = budget + attention.
A3: Company | B3: Country | C3: Why it's a strong fit | D3: Suggested opening angle
A4: General Aviation Service (G.A.S.) | B4: Spain | C4: 9 Spanish FBO bases, ~100 staff, actively investing in new equipment (€200k in early 2025, TowFLEXX deployment). Multi-station coordination pain. Family-owned — decisions fast. | D4: Congratulate on TowFLEXX deployment in Alicante. Ask how they coordinate turn progress + equipment across 9 bases today — is it WhatsApp + email?
A5: GH Italia (Alisud) | B5: Italy | C5: 11+ Italian stations + LHR. Largest Italian independent. Recently under pressure from dnata consolidating Airport Handling SpA. | D5: Frame: 'while dnata integrates, you are the biggest truly Italian independent — want to stay that way long-term? Here's how an ops layer protects that.'
A6: Goldair Handling | B6: Greece | C6: Already ISO 27001 certified — CISO buys security claims easily. 160+ airline customers. Network: GR + CY + BG + IN + RS. 177k flights/yr. | D6: Lean on the ISO 27001 angle. They clearly value information-security sophistication. Show how dashboard audit trails + RBAC help the next recert.
A7: Skyserv Handling Services | B7: Greece | C7: 37 Greek airports — that is an enormous station-count for a single ops team to monitor. Island + seasonality variance makes real-time visibility valuable. | D7: Seasonality angle: 'how do your Mykonos, Santorini, Heraklion station managers share situational awareness in August peak?'
A8: Aviator (Nordic) | B8: Denmark / Nordics | C8: Largest independent handler in Nordics. 15 airports across 4 countries. Recently renewed + expanded AF-KL contract, signalling growth + reinvestment. | D8: The AF-KL renewal is fresh. Ask what they committed to the airline on ops visibility / on-time metrics — dashboard can deliver those SLAs.
A9: AHS Aviation Handling Services | B9: Germany | C9: Largest German independent — HAJ, DUS, HAM, STR (SGS JV), BRE, NUE (AirPart), LEJ (ASL partner), DRS (ASD partner). Clear traditional posture. Huge upside. | D9: Straight pitch: 'you're the biggest independent in Germany but your JV + partner structure means your data lives in 6 different places. Unify it.'
A10: Portway | B10: Portugal | C10: Vinci Airports subsidiary (via ANA). 1,600 employees, 5 Portuguese airports, 80+ airlines. Cargo-award heavy. Vinci will push digitisation across airports — perfect tailwind. | D10: The Vinci angle: 'other Vinci airports (e.g., London Gatwick) use modern digital ops tools — can support internal comparability pitch to ANA board.'
A11: Mallorcair | B11: Spain | C11: Just won Palma's FBO1 executive terminal contract. EMEA Top 10 FBO. Strong local brand. Island isolation = logistics complexity they already manage well. | D11: Congratulate on FBO1 award. Ask about their ops planning pre-summer peak — June to September is ~half their annual volume.
A12: Advanced Air Support (AAS) | B12: France | C12: ~15% private-av share at Le Bourget. Kept independence by joining Sky Valet Connect, so clearly values autonomy. Big equipment fleet. | D12: Autonomy angle: 'you joined Sky Valet Connect to get the brand, not the tools — the tools should be your own choice.'
A13: Advantage Flight Support (AFSL) | B13: UK | C13: Small independent biz-av FBO at EMA with supervisory network across multiple UK airports. Services LTN, STN, LBA, DSA, BHX, MAN, GLA. | D13: Multi-station supervisory pain — a single pane to track aircraft across 7 airports is exactly the problem.
A14: Euro Jet Intercontinental | B14: Czechia / Eastern Europe | C14: Prague HQ, ~200+ staff, agents in 29 countries + representation in 52 more. Ops complexity is their USP. Tech-forward. | D14: They already think in terms of coordination-across-borders. Ask what tool they use internally to keep 29-country network visible day-to-day.
... A18: Kurz Aviation Group | B18: Germany | C18: Operates STR (KAS), Cologne + Frankfurt (BAC). 25+ yr brand. Partner with ExecuJet + Jet Aviation + Air Elite — already in high-service segment. | D18: Premium-service angle: 'your customers (ExecuJet clients etc.) expect visibility; your competitors in biz-av all have dashboards; here's yours.'
